Workbook

Sheet Control
A1: LOGO | C1: Formato para estimación del balance del producto | F1: Identificación:
F2: SOFT-T-002
F3: Revisión: 0
C4: FELIX RUIZ GONZALEZ | F4: Inicio de vigencia:
F5: 45642
A10: DOCUMENTO CONTROLADO
A11: Autor de documento original: LOGC750219
A12: SOFT-T-002 Formato para estimación del balance del producto
A14: Copia controlada No. :0
B17: Nombre | D17: Puesto o función | F17: Firma | G17: Fecha
A18: Elaboró: | B18: Lezlie Anahy Gutierrez Armendáriz. | D18: Administrativo | G18: 45642
A19: Revisó: | B19: Félix Ruiz Gonzalez | D19: Alta Dirección | G19: 45642
A20: Aprobó: | B20: Félix Ruiz Gonzalez | D20: Alta Dirección | G20: 45642
A21: Localización del documento: | D21: Estación de servicio
A24: Control de cambios
A26: Estado | B26: Fecha de inicio de vigencia | C26: Revisión | D26: Descripción del cambio realizado | E26: Realizó | F26: Revisó | G26: Aprobó
A28: Vigente | B28: 45642 | C28: 0 | D28: Ninguno (versión original). | E28: LAGA | F28: FRG | G28: FRG
A48: Documento controlado, prohibida su reproducción parcial o total sin autorización. | F48: Página 1 de 8

Sheet Inventario Inicial
A13: Datos | F13: LECTURA INICIAL (Li)
A14: hx= | C14: m | D14: Valor de entrada
A15: h1= | C15: m | D15: Datos del certificado de calibración
A16: h2= | C16: m
A17: V1= | C17: m3
A18: V2= | C18: m3
A19: Acero al carbón (αc): | C19: 1/°C
A20: Ts= | C20: °C
A21: T liquido= | C21: °C
A22: T ambiente= | C22: °C
A25: RHO Observada: | C25: kg/m3 | D25: Datos obtenidos de un muestreo del producto
A26: T observada= | C26: °C
A27: T base= | C27: °C
A30: Volumen en hx= | B30: =(((B14-B15)/(B16-B15))*(B18-B17))+B17 -> #DIV/0! | C30: m3
A31: CTS= | B31: =1+B19*(B20-20) -> 1
A32: CTL= | B32: =C75/C76 -> #DIV/0!
B50: Aplicación del API 2540: | G50: K0=
B51: Iteración: | C51: 1 | G51: K1=
B52: Beta 15: | C52: =((H50/(B25^2))+(H51/B25)) -> #DIV/0!
B53: RHO 15= | C53: =B25/EXP(-C52*(B26-15)*(1+0.8*C52*(B26-15))) -> #DIV/0!
B55: Iteración: | C55: 2
B56: Beta 15: | C56: =((H50/(C53^2))+(H51/C53)) -> #DIV/0!
B57: RHO 15= | C57: =B25/EXP(-C56*(B26-15)*(1+0.8*C56*(B26-15))) -> #DIV/0!
B60: Iteración: | C60: 3
B61: Beta 15: | C61: =((H50/(C57^2))+(H51/C57)) -> #DIV/0!
B62: RHO 15= | C62: =B25/EXP(-C61*(B26-15)*(1+0.8*C61*(B26-15))) -> #DIV/0!
B65: Iteración: | C65: 4
B66: Beta 15: | C66: =((H50/(C62^2))+(H51/C62)) -> #DIV/0!
B67: RHO 15= | C67: =B25/EXP(-C66*(B26-15)*(1+0.8*C66*(B26-15))) -> #DIV/0!
B70: Iteración: | C70: 5
B71: Beta 15: | C71: =((H50/(C67^2))+(H51/C67)) -> #DIV/0!
B72: RHO 15= | C72: =B25/EXP(-C71*(B26-15)*(1+0.8*C71*(B26-15))) -> #DIV/0!
B73: Beta 20: | C73: =H50/C76^2+H51/C76 -> #DIV/0! | D73: 1/°C
B75: RHO a TS= | C75: =C72*EXP(-C71*(B20-15)*(1+0.8*C71*(B20-15))) -> #DIV/0! | D75: kg/m3 | E75: Densidad del producto
B76: RHO a 20= | C76: =C72*EXP(-C71*(20-15)*(1+0.8*C71*(20-15))) -> #DIV/0! | D76: kg/m3
B78: CTL= | C78: =C75/C76 -> #DIV/0!
B82: Resultado del ejercicio:
B83: Volumen base= | C83: =B30*B31*C78 -> #DIV/0! | D83: m3 | E83: Volumen neto, aplicando el CTL
A85: Estimación de Incertidumbre
A89: Presupuesto de incertidumbre en base al modelo
...

Sheet Derivadas Entradas
A1: Derivada del modelo de API para la Temperatura
A7: Para la derivada del coeficiente de sensibilidad de la temperatura para RHOtp y RHObase
A16: Dervida de V
H20: Primera derivada
H23: Segunda derivada
H35: Derivando con respecto a hx
K40: Derivando con respecto a h1
H45: Derivando con respecto a h2
G51: Derivando con respecto a v1
F56: Derivando con respecto a v2
F60: Derivando con respecto a αc
E64: Derivando con respecto a ts
F69: Derivando con respecto a RHOtp
F73: Derivando con respecto a RHObase

Sheet Inventario Final
A13: Datos | F13: LECTURA FINAL (Lf), Se realiza un mes después que la lectura inicial (por lo que cambian las temperaturas, densidad, etc.) además de que se mide a una altura del tanque distinta
A14: hx= | C14: m | D14: Valor de entrada
A15: h1= | C15: m | D15: Datos del certificado de calibración
A16: h2= | C16: m
A17: V1= | C17: m3
A18: V2= | C18: m3
A19: Acero al carbón: | C19: 1/°C | D19: αc
A20: Ts= | C20: °C
A21: T liquido= | C21: °C
A22: T ambiente= | C22: °C
A25: RHO Observada: | C25: kg/m3 | D25: Datos obtenidos de un muestreo del producto
A26: T observada= | C26: °C
A27: T base= | B27: 20 | C27: °C
A30: Volumen en hx= | B30: =(((B14-B15)/(B16-B15))*(B18-B17))+B17 -> #DIV/0! | C30: m3
A31: CTS= | B31: =1+B19*(B20-20) -> 1
A32: CTL= | B32: =C75/C76 -> #DIV/0!
B50: Aplicación del API 2540: | G50: K0=
B51: Iteración: | C51: 1 | G51: K1=
B52: Beta 15: | C52: =((H50/(B25^2))+(H51/B25)) -> #DIV/0!
B53: RHO 15= | C53: =B25/EXP(-C52*(B26-15)*(1+0.8*C52*(B26-15))) -> #DIV/0!
B55: Iteración: | C55: 2
B56: Beta 15: | C56: =((H50/(C53^2))+(H51/C53)) -> #DIV/0!
B57: RHO 15= | C57: =B25/EXP(-C56*(B26-15)*(1+0.8*C56*(B26-15))) -> #DIV/0!
B60: Iteración: | C60: 3
B61: Beta 15: | C61: =((H50/(C57^2))+(H51/C57)) -> #DIV/0!
B62: RHO 15= | C62: =B25/EXP(-C61*(B26-15)*(1+0.8*C61*(B26-15))) -> #DIV/0!
B65: Iteración: | C65: 4
B66: Beta 15: | C66: =((H50/(C62^2))+(H51/C62)) -> #DIV/0!
B67: RHO 15= | C67: =B25/EXP(-C66*(B26-15)*(1+0.8*C66*(B26-15))) -> #DIV/0!
B70: Iteración: | C70: 5
B71: Beta 15: | C71: =((H50/(C67^2))+(H51/C67)) -> #DIV/0!
B72: RHO 15= | C72: =B25/EXP(-C71*(B26-15)*(1+0.8*C71*(B26-15))) -> #DIV/0!
B73: Beta 20: | C73: =H50/C76^2+H51/C76 -> #DIV/0! | D73: 1/°C
B75: RHO a TS= | C75: =C72*EXP(-C71*(B20-15)*(1+0.8*C71*(B20-15))) -> #DIV/0! | D75: kg/m3 | E75: Densidad del producto
B76: RHO a 20= | C76: =C72*EXP(-C71*(20-15)*(1+0.8*C71*(20-15))) -> #DIV/0! | D76: kg/m3
B78: CTL= | C78: =C75/C76 -> #DIV/0!
B82: Resultado del ejercicio:
B83: Volumen base= | C83: =B30*B31*C78 -> #DIV/0! | D83: m3 | E83: Volumen neto, aplicando el CTL
A85: Estimación de Incertidumbre
A89: Presupuesto de incertidumbre en base al modelo
...

Sheet Presupuesto de U Salidas
A1: Posiciones de Salida o Llenado | F1: Medidores de salida: Turbinas, Coriolis, Desplazamiento positivo
A3: Caso 1 | B3: Terminal de distribución
A5: Medidor de flujo
A6: Temperatura
A7: Coeficiente de expansión térmico por producto (β20): | B7: Compensación de la lectura
A9: Se determina el volumen base de salida por posición
A13: Donde:
A14: FC: Factor de Calibración
A15: IV: Volumen indicado
A16: Vb= Volumen base
C17: Modelo para calcular la incertidumbre para un volumen base
A22: Volumen medido en el periodo: | B22: 1 mes (febrero) | G22: DISPENSARIO 2
A23: IV del periodo: | C23: L | D23: Datos supuestos de una medición | F23: TURNO 1 y 2 (AL MES)
A24: Gasto promedio: | C24: L/min
A25: Factor de calibración: | B25: 1 | C25: Adimensional
A27: β20 del producto: | B27: ='Inventario Final'!C73 -> #DIV/0! | C27: 1/°C
A28: Temperatura: | B28: 20 | C28: °C
B30: Min | C30: Max
A31: Variaciones de temperatura | F31: K-Factor: | G31: =400/20 -> 20 | H31: P/L | I31: pulsos por litro
A32: Variaciones de flujo | F32: Cargas: | H32: tanques
A34: Volumen Bruto: | B34: =B23*B25 -> 0 | C34: L
A35: CTL: | B35: =1-B27*(B28-20) -> #DIV/0!
A36: Volumen base: | B36: =B34*B35 -> #DIV/0! | C36: L
A38: Gasto promedio: | B38: =(C32+B32)/2 -> 0 | C38: L/min
A39: Linealidad:
A41: K-Factor anterior | B41: 20 | C41: P/L
A42: K-Factor nuevo | B42: 20 | C42: P/L
A44: KF Nuevo= KF anterior/Factor de Calibración nuevo
A45: Factor de Calibracion nuevo= KF anterior/KF nuevo
A46: FC nuevo= | B46: =B41/B42 -> 1 | C46: =(1-B46) -> 0 | D46: % de error de un K-factor a otro
A51: Estimación de Incertidumbre
A55: Presupuesto de incertidumbre con base al modelo
A57: Referencia | B57: Variable de entrada | E57: Valor | F57: Unidad | G57: Fuente de informacion | I57: U Original | J57: Tipo Distribución | K57: u(xi) | L57: Ci | M57: u(xi)*Ci | N57: [u(xi)*Ci]^2 | O57: Aportación en %
A58: 1 | B58: Volumen indicado por el medidor de manera directa (IV) | E58: =B23 -> 0 | F58: L | G58: Sistema de Control Central | I58: =G32/G31 -> 0 | J58: Uniforme | K58: =I58/SQRT(12) -> 0 | L58: =E60*(1-B27*(B28-20)) -> #DIV/0! | M58: =L58*K58 -> #DIV/0! | N58: =M58^2 -> #DIV/0! | O58: =N58/$N$78 -> #DIV/0!
A60: 2 | B60: Factor de Calibración (FC) | E60: =B25 -> 1 | F60: Adimensional | G60: Sitema de Llenado | I60: uc del FC | K60: =SQRT(N62+N64+N66) -> 0.0025 | L60: =B23*(1-B27*(B28-20)) -> #DIV/0! | M60: =L60*K60 -> #DIV/0! | N60: =M60^2 -> #DIV/0! | O60: =N60/$N$78 -> #DIV/0!
A62: 2.1 | B62: Certificado de Calibración | F62: Adimensional | G62: NOM-005-SCFI-2017 | I62: 0.005 | J62: Normal | K62: =I62/2 -> 0.0025 | L62: 1 | M62: =K62*L62 -> 0.0025 | N62: =M62^2 -> 6.25e-06
A64: 2.2 | B64: Estabilidad del flujo | F64: Adimensional | G64: UVIM | I64: =B39/2 -> 0 | J64: Normal | K64: =I64/2 -> 0 | L64: 1 | M64: =K64*L64 -> 0 | N64: =M64^2 -> 0
A66: 2.3 | B66: Deriva | F66: Adimensional | G66: UVIM | I66: =C46 -> 0 | J66: Normal | K66: =I66/2 -> 0 | L66: 1 | M66: =K66*L66 -> 0 | N66: =M66^2 -> 0
A68: 3 | B68: Coeficiente de expansión térmico del producto (β) | E68: =B27 -> #DIV/0! | F68: 1/°C | G68: Calidad del diesel | I68: =E68*0.1 -> #DIV/0! | J68: Uniforme | K68: =I68/SQRT(12) -> #DIV/0! | L68: =(-E58*E60)*(B28-20) -> 0 | M68: =L68*K68 -> #DIV/0! | N68: =M68^2 -> #DIV/0! | O68: =N68/$N$78 -> #DIV/0!
A70: 4 | B70: Temperatura promedio de carga (t) | E70: =B28 -> 20 | F70: °C | I70: uc de t | K70: =SQRT(N72+N74+N76) -> 0.028867513 | L70: =-E58*E60*B27 -> #DIV/0! | M70: =L70*K70 -> #DIV/0! | N70: =M70^2 -> #DIV/0! | O70: =N70/$N$78 -> #DIV/0!
...

Sheet Derivadas Salidas

Sheet Balance
P1: ui | Q1: Ci | R1: ui*Ci | S1: ui*Ci^2
G2: Li (Inventario): | H2: ='Inventario Inicial'!C83 -> #DIV/0! | I2: m3 | J2: Uexp, k=2: | K2: ='Inventario Inicial'!N147 -> #DIV/0! | L2: Se toman del final de las tablas de Presupuesto de U | N2: ='Inventario Inicial'!N146 -> #DIV/0! | O2: m3 | P2: =N2/2 -> #DIV/0! | Q2: -1 | R2: =P2*Q2 -> #DIV/0! | S2: =R2^2 -> #DIV/0! | Y2: Si el Factor esta 100% relacionado se va a tomar como la unidad (1)
G3: Lf (Inventario): | H3: ='Inventario Final'!C83 -> #DIV/0! | I3: m3 | J3: Uexp, k=2: | K3: ='Inventario Final'!N147 -> #DIV/0! | N3: ='Inventario Final'!N146 -> #DIV/0! | O3: m3 | P3: =N3/2 -> #DIV/0! | Q3: 1 | R3: =P3*Q3 -> #DIV/0! | S3: =R3^2 -> #DIV/0!
T4: P1 | U4: P2 | V4: P3 | W4: P4 | Y4: CORRELACION
G5: Salida-P1 (Disp. 2) | H5: ='Presupuesto de U Salidas'!B36/1000 -> #DIV/0! | I5: m3 | J5: Uexp, k=2: | K5: ='Presupuesto de U Salidas'!N81 -> #DIV/0! | N5: ='Presupuesto de U Salidas'!N80/1000 -> #DIV/0! | O5: m3 | P5: =N5/2 -> #DIV/0! | Q5: 1 | R5: =P5*Q5 -> #DIV/0! | S5: =R5^2 -> #DIV/0! | U5: =R5*R6 -> #DIV/0! | V5: =R5*R7 -> #DIV/0! | W5: =R5*R8 -> #DIV/0! | X5: =SUM(U5:W5) -> #DIV/0! | Z5: Significado de colores:
V6: =R6*R7 -> 0 | W6: =R6*R8 -> 0 | X6: =SUM(U6:W6) -> 0 | Z6: NO SE RELACIONA
W7: =R7*R8 -> 0 | X7: =SUM(U7:W7) -> 0 | Z7: No se puede llenar, es del escalon hacia la derecha
G9: Salidas totales: | H9: ='Presupuesto de U Salidas'!B36/1000 -> #DIV/0! | I9: m3 | R9: Sumatoria: | S9: =SUM(S5:S8,X9) -> #DIV/0! | T9: Se le suma la Sumatoria*2 | W9: Sumatoria*2: | X9: =SUM(X5:X7)*2 -> #DIV/0!
H10: =SUM(H5,H6)-H9 -> #DIV/0! | R10: Raíz, uc de Salidas: | S10: =SQRT(S9) -> #DIV/0! | T10: Incertidumbre combinada
R11: Uexp, k=2 | S11: =S10*2 -> #DIV/0! | T11: =S11/H9 -> #DIV/0! | U11: No podemos tener una u menor a la que le da origen
G13: Descarga: | I13: m3 | J13: Uexp, k=2 | K13: =K5 -> #DIV/0! | N13: =H13*K13 -> #DIV/0! | O13: m3 | P13: =N13/2 -> #DIV/0! | Q13: -1 | R13: =P13*Q13 -> #DIV/0! | S13: =R13^2 -> #DIV/0!
G15: Balance: | H15: =H3-H2+H9-H13 -> #DIV/0!
R16: Suma: | S16: =SUM(S2:S3,S5:S8,S13) -> #DIV/0!
R17: Raíz, uc de Balance: | S17: =SQRT(S16) -> #DIV/0!
G18: Evaluación del balance: | I18: =H15/S18 -> #DIV/0! | J18: =IF(ABS(I18)<1,"Cumple","No cumple") -> #DIV/0! | R18: Uexp, k=2 | S18: =S17*2 -> #DIV/0!
R22: Suma: | S22: =SUM(S2+S3+S13+S9) -> #DIV/0!
R23: Raíz, uc de Balance: | S23: =SQRT(S22) -> #DIV/0!
R24: Uexp, k=2 | S24: =S23*2 -> #DIV/0!
